[2024-02-10T00:27:35.847+0000] {taskinstance.py:1957} INFO - Dependencies all met for dep_context=non-requeueable deps ti=<TaskInstance: etl_weather_data.extract manual__2024-02-10T00:27:32.145590+00:00 [queued]>
[2024-02-10T00:27:35.856+0000] {taskinstance.py:1957} INFO - Dependencies all met for dep_context=requeueable deps ti=<TaskInstance: etl_weather_data.extract manual__2024-02-10T00:27:32.145590+00:00 [queued]>
[2024-02-10T00:27:35.857+0000] {taskinstance.py:2171} INFO - Starting attempt 1 of 2
[2024-02-10T00:27:36.014+0000] {taskinstance.py:2192} INFO - Executing <Task(PythonOperator): extract> on 2024-02-10 00:27:32.145590+00:00
[2024-02-10T00:27:36.019+0000] {standard_task_runner.py:60} INFO - Started process 93 to run task
[2024-02-10T00:27:36.023+0000] {standard_task_runner.py:87} INFO - Running: ['***', 'tasks', 'run', 'etl_weather_data', 'extract', 'manual__2024-02-10T00:27:32.145590+00:00', '--job-id', '7', '--raw', '--subdir', 'DAGS_FOLDER/etl_dag.py', '--cfg-path', '/tmp/tmp65z776m4']
[2024-02-10T00:27:36.027+0000] {standard_task_runner.py:88} INFO - Job 7: Subtask extract
[2024-02-10T00:27:36.077+0000] {task_command.py:423} INFO - Running <TaskInstance: etl_weather_data.extract manual__2024-02-10T00:27:32.145590+00:00 [running]> on host f4575c9010ae
[2024-02-10T00:27:36.152+0000] {taskinstance.py:2481} INFO - Exporting env vars: AIRFLOW_CTX_DAG_OWNER='Lucas Andrini' AIRFLOW_CTX_DAG_ID='etl_weather_data' AIRFLOW_CTX_TASK_ID='extract' AIRFLOW_CTX_EXECUTION_DATE='2024-02-10T00:27:32.145590+00:00' AIRFLOW_CTX_TRY_NUMBER='1' AIRFLOW_CTX_DAG_RUN_ID='manual__2024-02-10T00:27:32.145590+00:00'
[2024-02-10T00:27:36.154+0000] {etl_dag.py:55} INFO - Contenido de config.ini:
ItemsView(<configparser.ConfigParser object at 0x7f81ea2394c0>)
[2024-02-10T00:27:36.155+0000] {etl_dag.py:59} INFO - API KEY: None
[2024-02-10T00:27:36.155+0000] {taskinstance.py:2699} ERROR - Task failed with exception
Traceback (most recent call last):
  File "/home/airflow/.local/lib/python3.8/site-packages/airflow/models/taskinstance.py", line 433, in _execute_task
    result = execute_callable(context=context, **execute_callable_kwargs)
  File "/home/airflow/.local/lib/python3.8/site-packages/airflow/operators/python.py", line 199, in execute
    return_value = self.execute_callable()
  File "/home/airflow/.local/lib/python3.8/site-packages/airflow/operators/python.py", line 216, in execute_callable
    return self.python_callable(*self.op_args, **self.op_kwargs)
  File "/opt/airflow/dags/etl_dag.py", line 60, in extract
    cities = config.get('openweathermap', 'cities')  # Latitudes y longitudes de ciudades separadas por comas
  File "/usr/local/lib/python3.8/configparser.py", line 781, in get
    d = self._unify_values(section, vars)
  File "/usr/local/lib/python3.8/configparser.py", line 1149, in _unify_values
    raise NoSectionError(section) from None
configparser.NoSectionError: No section: 'openweathermap'
[2024-02-10T00:27:36.172+0000] {taskinstance.py:1138} INFO - Marking task as UP_FOR_RETRY. dag_id=etl_weather_data, task_id=extract, execution_date=20240210T002732, start_date=20240210T002735, end_date=20240210T002736
[2024-02-10T00:27:36.184+0000] {standard_task_runner.py:107} ERROR - Failed to execute job 7 for task extract (No section: 'openweathermap'; 93)
[2024-02-10T00:27:36.196+0000] {local_task_job_runner.py:234} INFO - Task exited with return code 1
[2024-02-10T00:27:36.224+0000] {taskinstance.py:3281} INFO - 0 downstream tasks scheduled from follow-on schedule check
