[2024-02-10T22:35:26.725+0000] {taskinstance.py:1957} INFO - Dependencies all met for dep_context=non-requeueable deps ti=<TaskInstance: etl_weather_data.extract manual__2024-02-10T22:35:24.233197+00:00 [queued]>
[2024-02-10T22:35:26.740+0000] {taskinstance.py:1957} INFO - Dependencies all met for dep_context=requeueable deps ti=<TaskInstance: etl_weather_data.extract manual__2024-02-10T22:35:24.233197+00:00 [queued]>
[2024-02-10T22:35:26.742+0000] {taskinstance.py:2171} INFO - Starting attempt 1 of 2
[2024-02-10T22:35:26.764+0000] {taskinstance.py:2192} INFO - Executing <Task(PythonOperator): extract> on 2024-02-10 22:35:24.233197+00:00
[2024-02-10T22:35:26.770+0000] {standard_task_runner.py:60} INFO - Started process 68 to run task
[2024-02-10T22:35:26.775+0000] {standard_task_runner.py:87} INFO - Running: ['***', 'tasks', 'run', 'etl_weather_data', 'extract', 'manual__2024-02-10T22:35:24.233197+00:00', '--job-id', '19', '--raw', '--subdir', 'DAGS_FOLDER/etl_dag.py', '--cfg-path', '/tmp/tmp4fjhqjt1']
[2024-02-10T22:35:26.782+0000] {standard_task_runner.py:88} INFO - Job 19: Subtask extract
[2024-02-10T22:35:26.864+0000] {task_command.py:423} INFO - Running <TaskInstance: etl_weather_data.extract manual__2024-02-10T22:35:24.233197+00:00 [running]> on host 26fcbe5ecfed
[2024-02-10T22:35:27.290+0000] {taskinstance.py:2481} INFO - Exporting env vars: AIRFLOW_CTX_DAG_OWNER='Lucas Andrini' AIRFLOW_CTX_DAG_ID='etl_weather_data' AIRFLOW_CTX_TASK_ID='extract' AIRFLOW_CTX_EXECUTION_DATE='2024-02-10T22:35:24.233197+00:00' AIRFLOW_CTX_TRY_NUMBER='1' AIRFLOW_CTX_DAG_RUN_ID='manual__2024-02-10T22:35:24.233197+00:00'
[2024-02-10T22:35:27.295+0000] {taskinstance.py:2699} ERROR - Task failed with exception
Traceback (most recent call last):
  File "/home/airflow/.local/lib/python3.8/site-packages/airflow/models/taskinstance.py", line 433, in _execute_task
    result = execute_callable(context=context, **execute_callable_kwargs)
  File "/home/airflow/.local/lib/python3.8/site-packages/airflow/operators/python.py", line 199, in execute
    return_value = self.execute_callable()
  File "/home/airflow/.local/lib/python3.8/site-packages/airflow/operators/python.py", line 216, in execute_callable
    return self.python_callable(*self.op_args, **self.op_kwargs)
  File "/opt/airflow/dags/etl_dag.py", line 51, in extract
    api_key = config.get('openweathermap', 'api_key')
  File "/usr/local/lib/python3.8/configparser.py", line 781, in get
    d = self._unify_values(section, vars)
  File "/usr/local/lib/python3.8/configparser.py", line 1149, in _unify_values
    raise NoSectionError(section) from None
configparser.NoSectionError: No section: 'openweathermap'
[2024-02-10T22:35:27.322+0000] {taskinstance.py:1138} INFO - Marking task as UP_FOR_RETRY. dag_id=etl_weather_data, task_id=extract, execution_date=20240210T223524, start_date=20240210T223526, end_date=20240210T223527
[2024-02-10T22:35:27.352+0000] {standard_task_runner.py:107} ERROR - Failed to execute job 19 for task extract (No section: 'openweathermap'; 68)
[2024-02-10T22:35:27.391+0000] {local_task_job_runner.py:234} INFO - Task exited with return code 1
[2024-02-10T22:35:27.448+0000] {taskinstance.py:3281} INFO - 0 downstream tasks scheduled from follow-on schedule check
