[2024-02-09T23:58:23.396+0000] {taskinstance.py:1957} INFO - Dependencies all met for dep_context=non-requeueable deps ti=<TaskInstance: etl_weather_data.extract manual__2024-02-09T23:57:15.206023+00:00 [queued]>
[2024-02-09T23:58:23.457+0000] {taskinstance.py:1957} INFO - Dependencies all met for dep_context=requeueable deps ti=<TaskInstance: etl_weather_data.extract manual__2024-02-09T23:57:15.206023+00:00 [queued]>
[2024-02-09T23:58:23.466+0000] {taskinstance.py:2171} INFO - Starting attempt 2 of 2
[2024-02-09T23:58:23.559+0000] {taskinstance.py:2192} INFO - Executing <Task(PythonOperator): extract> on 2024-02-09 23:57:15.206023+00:00
[2024-02-09T23:58:23.584+0000] {standard_task_runner.py:60} INFO - Started process 88 to run task
[2024-02-09T23:58:23.601+0000] {standard_task_runner.py:87} INFO - Running: ['***', 'tasks', 'run', 'etl_weather_data', 'extract', 'manual__2024-02-09T23:57:15.206023+00:00', '--job-id', '16', '--raw', '--subdir', 'DAGS_FOLDER/etl_dag.py', '--cfg-path', '/tmp/tmpk_jt1r8f']
[2024-02-09T23:58:23.614+0000] {standard_task_runner.py:88} INFO - Job 16: Subtask extract
[2024-02-09T23:58:23.899+0000] {task_command.py:423} INFO - Running <TaskInstance: etl_weather_data.extract manual__2024-02-09T23:57:15.206023+00:00 [running]> on host 098a85d63f89
[2024-02-09T23:58:25.030+0000] {taskinstance.py:2481} INFO - Exporting env vars: AIRFLOW_CTX_DAG_OWNER='Lucas Andrini' AIRFLOW_CTX_DAG_ID='etl_weather_data' AIRFLOW_CTX_TASK_ID='extract' AIRFLOW_CTX_EXECUTION_DATE='2024-02-09T23:57:15.206023+00:00' AIRFLOW_CTX_TRY_NUMBER='2' AIRFLOW_CTX_DAG_RUN_ID='manual__2024-02-09T23:57:15.206023+00:00'
[2024-02-09T23:58:25.035+0000] {taskinstance.py:2699} ERROR - Task failed with exception
Traceback (most recent call last):
  File "/home/airflow/.local/lib/python3.8/site-packages/airflow/models/taskinstance.py", line 433, in _execute_task
    result = execute_callable(context=context, **execute_callable_kwargs)
  File "/home/airflow/.local/lib/python3.8/site-packages/airflow/operators/python.py", line 199, in execute
    return_value = self.execute_callable()
  File "/home/airflow/.local/lib/python3.8/site-packages/airflow/operators/python.py", line 216, in execute_callable
    return self.python_callable(*self.op_args, **self.op_kwargs)
  File "/opt/airflow/dags/etl_dag.py", line 56, in extract
    cities = config.get('openweathermap', 'cities')  # Latitudes y longitudes de ciudades separadas por comas
  File "/usr/local/lib/python3.8/configparser.py", line 781, in get
    d = self._unify_values(section, vars)
  File "/usr/local/lib/python3.8/configparser.py", line 1149, in _unify_values
    raise NoSectionError(section) from None
configparser.NoSectionError: No section: 'openweathermap'
[2024-02-09T23:58:25.094+0000] {taskinstance.py:1138} INFO - Marking task as FAILED. dag_id=etl_weather_data, task_id=extract, execution_date=20240209T235715, start_date=20240209T235823, end_date=20240209T235825
[2024-02-09T23:58:25.177+0000] {standard_task_runner.py:107} ERROR - Failed to execute job 16 for task extract (No section: 'openweathermap'; 88)
[2024-02-09T23:58:25.269+0000] {local_task_job_runner.py:234} INFO - Task exited with return code 1
[2024-02-09T23:58:25.434+0000] {taskinstance.py:3281} INFO - 0 downstream tasks scheduled from follow-on schedule check
