[2024-02-10T14:42:44.848+0000] {taskinstance.py:1957} INFO - Dependencies all met for dep_context=non-requeueable deps ti=<TaskInstance: etl_weather_data.transform manual__2024-02-10T14:41:33.670859+00:00 [queued]>
[2024-02-10T14:42:44.858+0000] {taskinstance.py:1957} INFO - Dependencies all met for dep_context=requeueable deps ti=<TaskInstance: etl_weather_data.transform manual__2024-02-10T14:41:33.670859+00:00 [queued]>
[2024-02-10T14:42:44.859+0000] {taskinstance.py:2171} INFO - Starting attempt 2 of 2
[2024-02-10T14:42:44.872+0000] {taskinstance.py:2192} INFO - Executing <Task(PythonOperator): transform> on 2024-02-10 14:41:33.670859+00:00
[2024-02-10T14:42:44.877+0000] {standard_task_runner.py:60} INFO - Started process 101 to run task
[2024-02-10T14:42:44.881+0000] {standard_task_runner.py:87} INFO - Running: ['***', 'tasks', 'run', 'etl_weather_data', 'transform', 'manual__2024-02-10T14:41:33.670859+00:00', '--job-id', '16', '--raw', '--subdir', 'DAGS_FOLDER/etl_dag.py', '--cfg-path', '/tmp/tmpki53vd5p']
[2024-02-10T14:42:44.884+0000] {standard_task_runner.py:88} INFO - Job 16: Subtask transform
[2024-02-10T14:42:44.931+0000] {task_command.py:423} INFO - Running <TaskInstance: etl_weather_data.transform manual__2024-02-10T14:41:33.670859+00:00 [running]> on host 0e148b35b323
[2024-02-10T14:42:45.140+0000] {taskinstance.py:2481} INFO - Exporting env vars: AIRFLOW_CTX_DAG_OWNER='Lucas Andrini' AIRFLOW_CTX_DAG_ID='etl_weather_data' AIRFLOW_CTX_TASK_ID='transform' AIRFLOW_CTX_EXECUTION_DATE='2024-02-10T14:41:33.670859+00:00' AIRFLOW_CTX_TRY_NUMBER='2' AIRFLOW_CTX_DAG_RUN_ID='manual__2024-02-10T14:41:33.670859+00:00'
[2024-02-10T14:42:45.144+0000] {taskinstance.py:2699} ERROR - Task failed with exception
Traceback (most recent call last):
  File "/home/airflow/.local/lib/python3.8/site-packages/airflow/models/taskinstance.py", line 433, in _execute_task
    result = execute_callable(context=context, **execute_callable_kwargs)
  File "/home/airflow/.local/lib/python3.8/site-packages/airflow/operators/python.py", line 199, in execute
    return_value = self.execute_callable()
  File "/home/airflow/.local/lib/python3.8/site-packages/airflow/operators/python.py", line 216, in execute_callable
    return self.python_callable(*self.op_args, **self.op_kwargs)
  File "/opt/airflow/dags/etl_dag.py", line 97, in transform
    df_extracted = pd.read_csv(extract_csv_path, converters={'coord': eval, 'weather': ast.literal_eval, 'main': eval, 'wind': eval, 'sys': eval})
  File "/home/airflow/.local/lib/python3.8/site-packages/pandas/io/parsers/readers.py", line 912, in read_csv
    return _read(filepath_or_buffer, kwds)
  File "/home/airflow/.local/lib/python3.8/site-packages/pandas/io/parsers/readers.py", line 577, in _read
    parser = TextFileReader(filepath_or_buffer, **kwds)
  File "/home/airflow/.local/lib/python3.8/site-packages/pandas/io/parsers/readers.py", line 1407, in __init__
    self._engine = self._make_engine(f, self.engine)
  File "/home/airflow/.local/lib/python3.8/site-packages/pandas/io/parsers/readers.py", line 1679, in _make_engine
    return mapping[engine](f, **self.options)
  File "/home/airflow/.local/lib/python3.8/site-packages/pandas/io/parsers/c_parser_wrapper.py", line 93, in __init__
    self._reader = parsers.TextReader(src, **kwds)
  File "pandas/_libs/parsers.pyx", line 557, in pandas._libs.parsers.TextReader.__cinit__
pandas.errors.EmptyDataError: No columns to parse from file
[2024-02-10T14:42:45.158+0000] {taskinstance.py:1138} INFO - Marking task as FAILED. dag_id=etl_weather_data, task_id=transform, execution_date=20240210T144133, start_date=20240210T144244, end_date=20240210T144245
[2024-02-10T14:42:45.169+0000] {standard_task_runner.py:107} ERROR - Failed to execute job 16 for task transform (No columns to parse from file; 101)
[2024-02-10T14:42:45.214+0000] {local_task_job_runner.py:234} INFO - Task exited with return code 1
[2024-02-10T14:42:45.241+0000] {taskinstance.py:3281} INFO - 0 downstream tasks scheduled from follow-on schedule check
