[2024-02-10T23:12:24.759+0000] {taskinstance.py:1957} INFO - Dependencies all met for dep_context=non-requeueable deps ti=<TaskInstance: etl_weather_data.transform manual__2024-02-10T23:04:38.076330+00:00 [queued]>
[2024-02-10T23:12:24.848+0000] {taskinstance.py:1957} INFO - Dependencies all met for dep_context=requeueable deps ti=<TaskInstance: etl_weather_data.transform manual__2024-02-10T23:04:38.076330+00:00 [queued]>
[2024-02-10T23:12:24.864+0000] {taskinstance.py:2171} INFO - Starting attempt 2 of 2
[2024-02-10T23:12:25.277+0000] {taskinstance.py:2192} INFO - Executing <Task(PythonOperator): transform> on 2024-02-10 23:04:38.076330+00:00
[2024-02-10T23:12:25.314+0000] {standard_task_runner.py:60} INFO - Started process 106 to run task
[2024-02-10T23:12:25.370+0000] {standard_task_runner.py:87} INFO - Running: ['***', 'tasks', 'run', 'etl_weather_data', 'transform', 'manual__2024-02-10T23:04:38.076330+00:00', '--job-id', '12', '--raw', '--subdir', 'DAGS_FOLDER/etl_dag.py', '--cfg-path', '/tmp/tmpuag06tee']
[2024-02-10T23:12:25.420+0000] {standard_task_runner.py:88} INFO - Job 12: Subtask transform
[2024-02-10T23:12:25.989+0000] {task_command.py:423} INFO - Running <TaskInstance: etl_weather_data.transform manual__2024-02-10T23:04:38.076330+00:00 [running]> on host dffe7b1315cb
[2024-02-10T23:12:27.414+0000] {taskinstance.py:2481} INFO - Exporting env vars: AIRFLOW_CTX_DAG_OWNER='Lucas Andrini' AIRFLOW_CTX_DAG_ID='etl_weather_data' AIRFLOW_CTX_TASK_ID='transform' AIRFLOW_CTX_EXECUTION_DATE='2024-02-10T23:04:38.076330+00:00' AIRFLOW_CTX_TRY_NUMBER='2' AIRFLOW_CTX_DAG_RUN_ID='manual__2024-02-10T23:04:38.076330+00:00'
[2024-02-10T23:12:27.503+0000] {taskinstance.py:2699} ERROR - Task failed with exception
Traceback (most recent call last):
  File "/home/airflow/.local/lib/python3.8/site-packages/airflow/models/taskinstance.py", line 433, in _execute_task
    result = execute_callable(context=context, **execute_callable_kwargs)
  File "/home/airflow/.local/lib/python3.8/site-packages/airflow/operators/python.py", line 199, in execute
    return_value = self.execute_callable()
  File "/home/airflow/.local/lib/python3.8/site-packages/airflow/operators/python.py", line 216, in execute_callable
    return self.python_callable(*self.op_args, **self.op_kwargs)
  File "/opt/airflow/dags/etl_dag.py", line 131, in transform
    fila_transformed['country'] = fila['sys']['country']
KeyError: 'country'
[2024-02-10T23:12:27.662+0000] {taskinstance.py:1138} INFO - Marking task as FAILED. dag_id=etl_weather_data, task_id=transform, execution_date=20240210T230438, start_date=20240210T231224, end_date=20240210T231227
[2024-02-10T23:12:27.795+0000] {standard_task_runner.py:107} ERROR - Failed to execute job 12 for task transform ('country'; 106)
[2024-02-10T23:12:27.959+0000] {local_task_job_runner.py:234} INFO - Task exited with return code 1
[2024-02-10T23:12:28.376+0000] {taskinstance.py:3281} INFO - 0 downstream tasks scheduled from follow-on schedule check
