[2024-02-10T23:11:23.029+0000] {taskinstance.py:1957} INFO - Dependencies all met for dep_context=non-requeueable deps ti=<TaskInstance: etl_weather_data.transform manual__2024-02-10T23:06:44.813006+00:00 [queued]>
[2024-02-10T23:11:23.104+0000] {taskinstance.py:1957} INFO - Dependencies all met for dep_context=requeueable deps ti=<TaskInstance: etl_weather_data.transform manual__2024-02-10T23:06:44.813006+00:00 [queued]>
[2024-02-10T23:11:23.108+0000] {taskinstance.py:2171} INFO - Starting attempt 1 of 2
[2024-02-10T23:11:23.176+0000] {taskinstance.py:2192} INFO - Executing <Task(PythonOperator): transform> on 2024-02-10 23:06:44.813006+00:00
[2024-02-10T23:11:23.190+0000] {standard_task_runner.py:60} INFO - Started process 84 to run task
[2024-02-10T23:11:23.200+0000] {standard_task_runner.py:87} INFO - Running: ['***', 'tasks', 'run', 'etl_weather_data', 'transform', 'manual__2024-02-10T23:06:44.813006+00:00', '--job-id', '10', '--raw', '--subdir', 'DAGS_FOLDER/etl_dag.py', '--cfg-path', '/tmp/tmpjpsfqad6']
[2024-02-10T23:11:23.217+0000] {standard_task_runner.py:88} INFO - Job 10: Subtask transform
[2024-02-10T23:11:23.442+0000] {task_command.py:423} INFO - Running <TaskInstance: etl_weather_data.transform manual__2024-02-10T23:06:44.813006+00:00 [running]> on host dffe7b1315cb
[2024-02-10T23:11:24.388+0000] {taskinstance.py:2481} INFO - Exporting env vars: AIRFLOW_CTX_DAG_OWNER='Lucas Andrini' AIRFLOW_CTX_DAG_ID='etl_weather_data' AIRFLOW_CTX_TASK_ID='transform' AIRFLOW_CTX_EXECUTION_DATE='2024-02-10T23:06:44.813006+00:00' AIRFLOW_CTX_TRY_NUMBER='1' AIRFLOW_CTX_DAG_RUN_ID='manual__2024-02-10T23:06:44.813006+00:00'
[2024-02-10T23:11:24.435+0000] {taskinstance.py:2699} ERROR - Task failed with exception
Traceback (most recent call last):
  File "/home/airflow/.local/lib/python3.8/site-packages/airflow/models/taskinstance.py", line 433, in _execute_task
    result = execute_callable(context=context, **execute_callable_kwargs)
  File "/home/airflow/.local/lib/python3.8/site-packages/airflow/operators/python.py", line 199, in execute
    return_value = self.execute_callable()
  File "/home/airflow/.local/lib/python3.8/site-packages/airflow/operators/python.py", line 216, in execute_callable
    return self.python_callable(*self.op_args, **self.op_kwargs)
  File "/opt/airflow/dags/etl_dag.py", line 131, in transform
    fila_transformed['country'] = fila['sys']['country']
KeyError: 'country'
[2024-02-10T23:11:24.503+0000] {taskinstance.py:1138} INFO - Marking task as UP_FOR_RETRY. dag_id=etl_weather_data, task_id=transform, execution_date=20240210T230644, start_date=20240210T231123, end_date=20240210T231124
[2024-02-10T23:11:24.578+0000] {standard_task_runner.py:107} ERROR - Failed to execute job 10 for task transform ('country'; 84)
[2024-02-10T23:11:24.636+0000] {local_task_job_runner.py:234} INFO - Task exited with return code 1
[2024-02-10T23:11:24.773+0000] {taskinstance.py:3281} INFO - 0 downstream tasks scheduled from follow-on schedule check
