[2024-02-10T23:12:32.046+0000] {taskinstance.py:1957} INFO - Dependencies all met for dep_context=non-requeueable deps ti=<TaskInstance: etl_weather_data.transform manual__2024-02-10T23:06:44.813006+00:00 [queued]>
[2024-02-10T23:12:32.159+0000] {taskinstance.py:1957} INFO - Dependencies all met for dep_context=requeueable deps ti=<TaskInstance: etl_weather_data.transform manual__2024-02-10T23:06:44.813006+00:00 [queued]>
[2024-02-10T23:12:32.197+0000] {taskinstance.py:2171} INFO - Starting attempt 2 of 2
[2024-02-10T23:12:32.357+0000] {taskinstance.py:2192} INFO - Executing <Task(PythonOperator): transform> on 2024-02-10 23:06:44.813006+00:00
[2024-02-10T23:12:32.395+0000] {standard_task_runner.py:60} INFO - Started process 109 to run task
[2024-02-10T23:12:32.401+0000] {standard_task_runner.py:87} INFO - Running: ['***', 'tasks', 'run', 'etl_weather_data', 'transform', 'manual__2024-02-10T23:06:44.813006+00:00', '--job-id', '13', '--raw', '--subdir', 'DAGS_FOLDER/etl_dag.py', '--cfg-path', '/tmp/tmp36dk681l']
[2024-02-10T23:12:32.430+0000] {standard_task_runner.py:88} INFO - Job 13: Subtask transform
[2024-02-10T23:12:32.846+0000] {task_command.py:423} INFO - Running <TaskInstance: etl_weather_data.transform manual__2024-02-10T23:06:44.813006+00:00 [running]> on host dffe7b1315cb
[2024-02-10T23:12:34.444+0000] {taskinstance.py:2481} INFO - Exporting env vars: AIRFLOW_CTX_DAG_OWNER='Lucas Andrini' AIRFLOW_CTX_DAG_ID='etl_weather_data' AIRFLOW_CTX_TASK_ID='transform' AIRFLOW_CTX_EXECUTION_DATE='2024-02-10T23:06:44.813006+00:00' AIRFLOW_CTX_TRY_NUMBER='2' AIRFLOW_CTX_DAG_RUN_ID='manual__2024-02-10T23:06:44.813006+00:00'
[2024-02-10T23:12:34.515+0000] {taskinstance.py:2699} ERROR - Task failed with exception
Traceback (most recent call last):
  File "/home/airflow/.local/lib/python3.8/site-packages/airflow/models/taskinstance.py", line 433, in _execute_task
    result = execute_callable(context=context, **execute_callable_kwargs)
  File "/home/airflow/.local/lib/python3.8/site-packages/airflow/operators/python.py", line 199, in execute
    return_value = self.execute_callable()
  File "/home/airflow/.local/lib/python3.8/site-packages/airflow/operators/python.py", line 216, in execute_callable
    return self.python_callable(*self.op_args, **self.op_kwargs)
  File "/opt/airflow/dags/etl_dag.py", line 131, in transform
    fila_transformed['country'] = fila['sys']['country']
KeyError: 'country'
[2024-02-10T23:12:34.580+0000] {taskinstance.py:1138} INFO - Marking task as FAILED. dag_id=etl_weather_data, task_id=transform, execution_date=20240210T230644, start_date=20240210T231232, end_date=20240210T231234
[2024-02-10T23:12:34.645+0000] {standard_task_runner.py:107} ERROR - Failed to execute job 13 for task transform ('country'; 109)
[2024-02-10T23:12:34.722+0000] {local_task_job_runner.py:234} INFO - Task exited with return code 1
[2024-02-10T23:12:34.884+0000] {taskinstance.py:3281} INFO - 0 downstream tasks scheduled from follow-on schedule check
